<?xml version="1.0" ?>
<!-- =================================================================================== -->
<!-- |    This document was autogenerated by xacro from alfarobi_compose.urdf.xacro    | -->
<!-- |    EDITING THIS FILE BY HAND IS NOT RECOMMENDED                                 | -->
<!-- =================================================================================== -->
<robot name="alfarobi">
  <material name="black">
    <color rgba="0.0 0.0 0.0 1.0"/>
  </material>
  <material name="blue">
    <color rgba="0.0 0.0 0.8 1.0"/>
  </material>
  <material name="green">
    <color rgba="0.0 0.8 0.0 1.0"/>
  </material>
  <material name="grey">
    <color rgba="0.60 0.60 0.60 1.0"/>
  </material>
  <material name="orange">
    <color rgba="1.0 0.4235294117647059 0.0392156862745098 1.0"/>
  </material>
  <material name="brown">
    <color rgba="0.8705882352941177 0.8117647058823529 0.7647058823529411 1.0"/>
  </material>
  <material name="red">
    <color rgba="0.8 0.0 0.0 1.0"/>
  </material>
  <material name="white">
    <color rgba="1.0 1.0 1.0 1.0"/>
  </material>
  <material name="beige">
    <color rgba="0.98 0.915 0.72 1.0"/>
  </material>
  <material name="temp">
    <color rgba="0.5 0.5 0.8 1.0"/>
  </material>

  <link name="base_link">
  </link>

  <joint name="base_to_link1" type="fixed">
    <parent link="base_link" />
    <child link="body_link" />
    <origin xyz="0 0 0.278" rpy="0 0 0" /> 
  </joint>

  <!--   body link-->
  <link name="body_link">
    <visual>
      <origin rpy="0 0 0" xyz="0 0 0"/>
      <geometry>
        <mesh filename="file:///home/lexciese/Dev/in-development/altair_ws/install/altair_description/share/altair_description/meshes/body.stl" scale="1 1 1"/>
      </geometry>
      <material name="Grey">
        <color rgba="0.60 0.60 0.60 1.0"/>
      </material>
    </visual>
    <collision>
      <origin rpy="0 0 0" xyz="0 0 0" />
      <geometry>
        <mesh filename="file:///home/lexciese/Dev/in-development/altair_ws/install/altair_description/share/altair_description/meshes/body.stl" scale="1 1 1"/>
      </geometry>
      <material name="Grey">
        <color rgba="0.60 0.60 0.60 1.0"/>
      </material>
    </collision>
    <inertial>
      <origin xyz="-0.01501 0.00013 0.06582"/>
      <mass value="1.34928"/>
      <inertia ixx="0.00340499" ixy="0.00000572" ixz="-0.00004256" iyy="0.00296939" iyz="-0.00000059" izz="0.00317331"/>
      <!--<inertia ixx="1.0" ixy="0.0" ixz="0.0" iyy="1.0" iyz="0.0" izz="1.0" />-->
    </inertial>
  </link>
  <!-- imu joint -->
  <joint name="imu_fixed" type="fixed">
    <parent link="body_link"/>
    <child link="imu_link"/>
    <origin rpy="0 0 0" xyz="0 0 0"/>
  </joint>
  <link name="imu_link"/>
  <!-- left hip yaw joint -->
  <joint name="l_hip_yaw" type="revolute">
    <parent link="body_link"/>
    <child link="l_hip_yaw_link"/>
    <origin rpy="0 0 0" xyz="0.0 0.035 0.0"/>
    <axis xyz="0 0 -1"/>
    <limit effort="1000" lower="-2.827433388230814" upper="2.827433388230814" velocity="100"/>
    <dynamics damping="0.1" friction="0.0"/>
  </joint>
  <!-- left hip yaw link -->
  <link name="l_hip_yaw_link">
    <visual>
      <origin rpy="0 0 0" xyz="0 0 0"/>
      <geometry>
        <mesh filename="file:///home/lexciese/Dev/in-development/altair_ws/install/altair_description/share/altair_description/meshes/ll1.stl" scale="1 1 1"/>
      </geometry>
      <material name="Grey">
        <color rgba="0.60 0.60 0.60 1.0"/>
      </material>
    </visual>
    <collision>
      <origin rpy="0 0 0" xyz="0 0 0"/>
      <geometry>
        <mesh filename="file:///home/lexciese/Dev/in-development/altair_ws/install/altair_description/share/altair_description/meshes/ll1.stl" scale="1 1 1"/>
      </geometry>
      <material name="Grey">
        <color rgba="0.60 0.60 0.60 1.0"/>
      </material>
    </collision>
    <inertial>
      <origin xyz="-0.00157 0.00000 -0.00774"/>
      <mass value="0.01181"/>
      <inertia ixx="0.00000151" ixy="0.0" ixz="0.00000001" iyy="0.00000430" iyz="0.0" izz="0.00000412"/>
    </inertial>
  </link>
  <!-- left hip roll joint -->
  <joint name="l_hip_roll" type="revolute">
    <parent link="l_hip_yaw_link"/>
    <child link="l_hip_roll_link"/>
    <origin rpy="0 0 0" xyz="-0.024 0.0 -0.0285"/>
    <axis xyz="-1 0 0"/>
    <limit effort="1000" lower="-2.827433388230814" upper="2.827433388230814" velocity="100"/>
    <dynamics damping="0.1" friction="0.0"/>
  </joint>
  <!-- left hip roll link -->
  <link name="l_hip_roll_link">
    <visual>
      <origin rpy="0 0 0" xyz="0 0 0"/>
      <geometry>
        <mesh filename="file:///home/lexciese/Dev/in-development/altair_ws/install/altair_description/share/altair_description/meshes/ll2.stl" scale="1 1 1"/>
      </geometry>
      <material name="Grey">
        <color rgba="0.60 0.60 0.60 1.0"/>
      </material>
    </visual>
    <collision>
      <origin rpy="0 0 0" xyz="0 0 0"/>
      <geometry>
        <mesh filename="file:///home/lexciese/Dev/in-development/altair_ws/install/altair_description/share/altair_description/meshes/ll2.stl" scale="1 1 1"/>
      </geometry>
      <material name="Grey">
        <color rgba="0.60 0.60 0.60 1.0"/>
      </material>
    </collision>
    <inertial>
      <origin xyz="0.00388 0.00028 -0.01214"/>
      <mass value="0.17886"/>
      <inertia ixx="0.00004661" ixy="-0.00000101" ixz="-0.00000131" iyy="0.00012523" iyz="-0.00000006" izz="0.00010857"/>
    </inertial>
  </link>
  <!-- left hip pitch joint -->
  <joint name="l_hip_pitch" type="revolute">
    <parent link="l_hip_roll_link"/>
    <child link="l_hip_pitch_link"/>
    <origin rpy="0 0 0" xyz="0.0241 0.019 0.0"/>
    <axis xyz="0 1 0"/>
    <limit effort="1000" lower="-2.827433388230814" upper="2.827433388230814" velocity="100"/>
    <dynamics damping="0.1" friction="0.0"/>
  </joint>
  <!-- left hip pitch link -->
  <link name="l_hip_pitch_link">
    <visual>
      <origin rpy="0 0 0" xyz="0 0 0"/>
      <geometry>
        <mesh filename="file:///home/lexciese/Dev/in-development/altair_ws/install/altair_description/share/altair_description/meshes/ll3.stl" scale="1 1 1"/>
      </geometry>
      <material name="Grey">
        <color rgba="0.60 0.60 0.60 1.0"/>
      </material>
    </visual>
    <collision>
      <origin rpy="0 0 0" xyz="0 0 0"/>
      <geometry>
        <mesh filename="file:///home/lexciese/Dev/in-development/altair_ws/install/altair_description/share/altair_description/meshes/ll3.stl" scale="1 1 1"/>
      </geometry>
      <material name="Grey">
        <color rgba="0.60 0.60 0.60 1.0"/>
      </material>
    </collision>
    <inertial>
      <origin xyz="0.00059 -0.01901 -0.08408"/>
      <mass value="0.11543"/>
      <inertia ixx="0.00010499" ixy="-0.00000001" ixz="-0.00000071" iyy="0.00009613" iyz="0.00000353" izz="0.00002493"/>
    </inertial>
  </link>
  <!-- left knee joint -->
  <joint name="l_knee" type="revolute">
    <parent link="l_hip_pitch_link"/>
    <child link="l_knee_link"/>
    <origin rpy="0 0 0" xyz="0.0 0.0 -0.11015"/>
    <axis xyz="0 1 0"/>
    <limit effort="1000" lower="-2.827433388230814" upper="2.827433388230814" velocity="100"/>
    <dynamics damping="0.1" friction="0.0"/>
  </joint>
  <!-- left hip pitch link -->
  <link name="l_knee_link">
    <visual>
      <origin rpy="0 0 0" xyz="0 0 0"/>
      <geometry>
        <mesh filename="file:///home/lexciese/Dev/in-development/altair_ws/install/altair_description/share/altair_description/meshes/ll4.stl" scale="1 1 1"/>
      </geometry>
      <material name="Grey">
        <color rgba="0.60 0.60 0.60 1.0"/>
      </material>
    </visual>
    <collision>
      <origin rpy="0 0 0" xyz="0 0 0"/>
      <geometry>
        <mesh filename="file:///home/lexciese/Dev/in-development/altair_ws/install/altair_description/share/altair_description/meshes/ll4.stl" scale="1 1 1"/>
      </geometry>
      <material name="Grey">
        <color rgba="0.60 0.60 0.60 1.0"/>
      </material>
    </collision>
    <inertial>
      <origin xyz="0.00000 -0.02151 -0.05500"/>
      <mass value="0.04015"/>
      <inertia ixx="0.00003715" ixy="0.0" ixz="0.0" iyy="0.00002751" iyz="0.0" izz="0.00001511"/>
    </inertial>
  </link>
  <!-- left ankle pitch link -->
  <joint name="l_ank_pitch" type="revolute">
    <parent link="l_knee_link"/>
    <child link="l_ank_pitch_link"/>
    <origin rpy="0 0 0" xyz="0 0 -0.110"/>
    <axis xyz="0 -1 0"/>
    <limit effort="1000" lower="-2.827433388230814" upper="2.827433388230814" velocity="100"/>
    <dynamics damping="0.1" friction="0.0"/>
  </joint>
  <!-- left hip pitch link -->
  <link name="l_ank_pitch_link">
    <visual>
      <origin rpy="0 0 0" xyz="0 0 0"/>
      <geometry>
        <mesh filename="file:///home/lexciese/Dev/in-development/altair_ws/install/altair_description/share/altair_description/meshes/ll5.stl" scale="1 1 1"/>
      </geometry>
      <material name="Grey">
        <color rgba="0.60 0.60 0.60 1.0"/>
      </material>
    </visual>
    <collision>
      <origin rpy="0 0 0" xyz="0 0 0"/>
      <geometry>
        <mesh filename="file:///home/lexciese/Dev/in-development/altair_ws/install/altair_description/share/altair_description/meshes/ll5.stl" scale="1 1 1"/>
      </geometry>
      <material name="Grey">
        <color rgba="0.60 0.60 0.60 1.0"/>
      </material>
    </collision>
    <inertial>
      <origin xyz="-0.02022 -0.01872 0.01214"/>
      <mass value="0.17886"/>
      <inertia ixx="0.00004661" ixy="-0.00000101" ixz="0.00000131" iyy="0.00012523" iyz="0.00000006" izz="0.00010857"/>
    </inertial>
  </link>
  <!-- left ankle roll link -->
  <joint name="l_ank_roll" type="revolute">
    <parent link="l_ank_pitch_link"/>
    <child link="l_ank_roll_link"/>
    <origin rpy="0 0 0" xyz="-0.0241 -0.019 0"/>
    <axis xyz="1 0 0"/>
    <limit effort="1000" lower="-2.827433388230814" upper="2.827433388230814" velocity="100"/>
    <dynamics damping="0.1" friction="0.0"/>
  </joint>
  <!-- left hip roll link -->
  <link name="l_ank_roll_link">
    <visual>
      <origin rpy="0 0 0" xyz="0 0 0"/>
      <geometry>
        <mesh filename="file:///home/lexciese/Dev/in-development/altair_ws/install/altair_description/share/altair_description/meshes/ll6.stl" scale="1 1 1"/>
      </geometry>
      <material name="Grey">
        <color rgba="0.60 0.60 0.60 1.0"/>
      </material>
    </visual>
    <collision>
      <origin rpy="0 0 0" xyz="0 0 0"/>
      <geometry>
        <mesh filename="file:///home/lexciese/Dev/in-development/altair_ws/install/altair_description/share/altair_description/meshes/ll6.stl" scale="1 1 1"/>
      </geometry>
      <material name="Grey">
        <color rgba="0.60 0.60 0.60 1.0"/>
      </material>
    </collision>
    <inertial>
      <origin xyz="0.02373 0.01037 -0.02760"/>
      <mass value="0.06934"/>
      <inertia ixx="0.00004034" ixy="-0.00000019" ixz="0.00000012" iyy="0.00007874" iyz="0.00000101" izz="0.00011579"/>
    </inertial>
  </link>
  <!-- right hip yaw joint -->
  <joint name="r_hip_yaw" type="revolute">
    <parent link="body_link"/>
    <child link="r_hip_yaw_link"/>
    <origin rpy="0 0 0" xyz="0.0 -0.035 0.0"/>
    <axis xyz="0 0 -1"/>
    <limit effort="1000" lower="-2.827433388230814" upper="2.827433388230814" velocity="100"/>
    <dynamics damping="0.1" friction="0.0"/>
  </joint>
  <!-- right hip yaw link -->
  <link name="r_hip_yaw_link">
    <visual>
      <origin rpy="0 0 0" xyz="0 0 0"/>
      <geometry>
        <mesh filename="file:///home/lexciese/Dev/in-development/altair_ws/install/altair_description/share/altair_description/meshes/rl1.stl" scale="1 1 1"/>
      </geometry>
      <material name="Grey">
        <color rgba="0.60 0.60 0.60 1.0"/>
      </material>
    </visual>
    <collision>
      <origin rpy="0 0 0" xyz="0 0 0"/>
      <geometry>
        <mesh filename="file:///home/lexciese/Dev/in-development/altair_ws/install/altair_description/share/altair_description/meshes/rl1.stl" scale="1 1 1"/>
      </geometry>
      <material name="Grey">
        <color rgba="0.60 0.60 0.60 1.0"/>
      </material>
    </collision>
    <inertial>
      <origin xyz="-0.00157 0.00000 -0.00774"/>
      <mass value="0.01181"/>
      <inertia ixx="0.00000151" ixy="0.0" ixz="0.00000001" iyy="0.00000430" iyz="0.0" izz="0.00000412"/>
    </inertial>
  </link>
  <!-- right hip roll joint -->
  <joint name="r_hip_roll" type="revolute">
    <parent link="r_hip_yaw_link"/>
    <child link="r_hip_roll_link"/>
    <origin rpy="0 0 0" xyz="-0.024 0.0 -0.0285"/>
    <axis xyz="-1 0 0"/>
    <limit effort="1000" lower="-2.827433388230814" upper="2.827433388230814" velocity="100"/>
    <dynamics damping="0.1" friction="0.0"/>
  </joint>
  <!-- right hip roll link -->
  <link name="r_hip_roll_link">
    <visual>
      <origin rpy="0 0 0" xyz="0 0 0"/>
      <geometry>
        <mesh filename="file:///home/lexciese/Dev/in-development/altair_ws/install/altair_description/share/altair_description/meshes/rl2.stl" scale="1 1 1"/>
      </geometry>
      <material name="Grey">
        <color rgba="0.60 0.60 0.60 1.0"/>
      </material>
    </visual>
    <collision>
      <origin rpy="0 0 0" xyz="0 0 0"/>
      <geometry>
        <mesh filename="file:///home/lexciese/Dev/in-development/altair_ws/install/altair_description/share/altair_description/meshes/rl2.stl" scale="1 1 1"/>
      </geometry>
      <material name="Grey">
        <color rgba="0.60 0.60 0.60 1.0"/>
      </material>
    </collision>
    <inertial>
      <origin xyz="0.00388 -0.00028 -0.01214"/>
      <mass value="0.17886"/>
      <inertia ixx="0.00004661" ixy="0.00000101" ixz="-0.00000131" iyy="0.00012523" iyz="0.00000006" izz="0.00010857"/>
    </inertial>
  </link>
  <!-- right hip pitch joint -->
  <joint name="r_hip_pitch" type="revolute">
    <parent link="r_hip_roll_link"/>
    <child link="r_hip_pitch_link"/>
    <origin rpy="0 0 0" xyz="0.0241 -0.019 0.0"/>
    <axis xyz="0 -1 0"/>
    <limit effort="1000" lower="-2.827433388230814" upper="2.827433388230814" velocity="100"/>
    <dynamics damping="0.1" friction="0.0"/>
  </joint>
  <!-- right hip pitch link -->
  <link name="r_hip_pitch_link">
    <visual>
      <origin rpy="0 0 0" xyz="0 0 0"/>
      <geometry>
        <mesh filename="file:///home/lexciese/Dev/in-development/altair_ws/install/altair_description/share/altair_description/meshes/rl3.stl" scale="1 1 1"/>
      </geometry>
      <material name="Grey">
        <color rgba="0.60 0.60 0.60 1.0"/>
      </material>
    </visual>
    <collision>
      <origin rpy="0 0 0" xyz="0 0 0"/>
      <geometry>
        <mesh filename="file:///home/lexciese/Dev/in-development/altair_ws/install/altair_description/share/altair_description/meshes/rl3.stl" scale="1 1 1"/>
      </geometry>
      <material name="Grey">
        <color rgba="0.60 0.60 0.60 1.0"/>
      </material>
    </collision>
    <inertial>
      <origin xyz="0.00059 0.01901 -0.08408"/>
      <mass value="0.11543"/>
      <inertia ixx="0.00010499" ixy="0.00000001" ixz="-0.00000071" iyy="0.00009613" iyz="-0.00000353" izz="0.00002493"/>
    </inertial>
  </link>
  <!-- right knee joint -->
  <joint name="r_knee" type="revolute">
    <parent link="r_hip_pitch_link"/>
    <child link="r_knee_link"/>
    <origin rpy="0 0 0" xyz="0.0 0.0 -0.11015"/>
    <axis xyz="0 -1 0"/>
    <limit effort="1000" lower="-2.827433388230814" upper="2.827433388230814" velocity="100"/>
    <dynamics damping="0.1" friction="0.0"/>
  </joint>
  <!-- right hip pitch link -->
  <link name="r_knee_link">
    <visual>
      <origin rpy="0 0 0" xyz="0 0 0"/>
      <geometry>
        <mesh filename="file:///home/lexciese/Dev/in-development/altair_ws/install/altair_description/share/altair_description/meshes/rl4.stl" scale="1 1 1"/>
      </geometry>
      <material name="Grey">
        <color rgba="0.60 0.60 0.60 1.0"/>
      </material>
    </visual>
    <collision>
      <origin rpy="0 0 0" xyz="0 0 0"/>
      <geometry>
        <mesh filename="file:///home/lexciese/Dev/in-development/altair_ws/install/altair_description/share/altair_description/meshes/rl4.stl" scale="1 1 1"/>
      </geometry>
      <material name="Grey">
        <color rgba="0.60 0.60 0.60 1.0"/>
      </material>
    </collision>
    <inertial>
      <origin xyz="0.00000 0.02151 -0.05500"/>
      <mass value="0.04015"/>
      <inertia ixx="0.00003715" ixy="0.0" ixz="0.0" iyy="0.00002751" iyz="0.0" izz="0.00001511"/>
    </inertial>
  </link>
  <!-- right ankle pitch link -->
  <joint name="r_ank_pitch" type="revolute">
    <parent link="r_knee_link"/>
    <child link="r_ank_pitch_link"/>
    <origin rpy="0 0 0" xyz="0 0 -0.110"/>
    <axis xyz="0 1 0"/>
    <limit effort="1000" lower="-2.827433388230814" upper="2.827433388230814" velocity="100"/>
    <dynamics damping="0.1" friction="0.0"/>
  </joint>
  <!-- right hip pitch link -->
  <link name="r_ank_pitch_link">
    <visual>
      <origin rpy="0 0 0" xyz="0 0 0"/>
      <geometry>
        <mesh filename="file:///home/lexciese/Dev/in-development/altair_ws/install/altair_description/share/altair_description/meshes/rl5.stl" scale="1 1 1"/>
      </geometry>
      <material name="Grey">
        <color rgba="0.60 0.60 0.60 1.0"/>
      </material>
    </visual>
    <collision>
      <origin rpy="0 0 0" xyz="0 0 0"/>
      <geometry>
        <mesh filename="file:///home/lexciese/Dev/in-development/altair_ws/install/altair_description/share/altair_description/meshes/rl5.stl" scale="1 1 1"/>
      </geometry>
      <material name="Grey">
        <color rgba="0.60 0.60 0.60 1.0"/>
      </material>
    </collision>
    <inertial>
      <origin xyz="-0.02022 0.01872 0.01214"/>
      <mass value="0.17886"/>
      <inertia ixx="0.00004661" ixy="0.00000101" ixz="0.00000131" iyy="0.00012523" iyz="-0.00000006" izz="0.00010857"/>
    </inertial>
  </link>
  <!-- right ankle roll link -->
  <joint name="r_ank_roll" type="revolute">
    <parent link="r_ank_pitch_link"/>
    <child link="r_ank_roll_link"/>
    <origin rpy="0 0 0" xyz="-0.0241 0.019 0"/>
    <axis xyz="1 0 0"/>
    <limit effort="1000" lower="-2.827433388230814" upper="2.827433388230814" velocity="100"/>
    <dynamics damping="0.1" friction="0.0"/>
  </joint>
  <!-- right hip roll link -->
  <link name="r_ank_roll_link">
    <visual>
      <origin rpy="0 0 0" xyz="0 0 0"/>
      <geometry>
        <mesh filename="file:///home/lexciese/Dev/in-development/altair_ws/install/altair_description/share/altair_description/meshes/rl6.stl" scale="1 1 1"/>
      </geometry>
      <material name="Grey">
        <color rgba="0.60 0.60 0.60 1.0"/>
      </material>
    </visual>
    <collision>
      <origin rpy="0 0 0" xyz="0 0 0"/>
      <geometry>
        <mesh filename="file:///home/lexciese/Dev/in-development/altair_ws/install/altair_description/share/altair_description/meshes/rl6.stl" scale="1 1 1"/>
      </geometry>
      <material name="Grey">
        <color rgba="0.60 0.60 0.60 1.0"/>
      </material>
    </collision>
    <inertial>
      <origin xyz="0.02373 -0.01037 -0.02760"/>
      <mass value="0.06934"/>
      <inertia ixx="0.00004034" ixy="0.00000019" ixz="0.00000012" iyy="0.00007874" iyz="-0.00000101" izz="0.00011579"/>
    </inertial>
  </link>
  <!-- left shoulder pitch joint -->
  <joint name="l_sho_pitch" type="revolute">
    <parent link="body_link"/>
    <child link="l_sho_pitch_link"/>
    <origin rpy="0 0 0" xyz="-0.001 0.06 0.111"/>
    <axis xyz="0 1 0"/>
    <limit effort="1000" lower="-2.827433388230814" upper="2.827433388230814" velocity="100"/>
    <dynamics damping="0.1" friction="0.0"/>
  </joint>
  <!-- left shoulder pitch link -->
  <link name="l_sho_pitch_link">
    <visual>
      <origin rpy="0 0 0" xyz="0 0 0"/>
      <geometry>
        <mesh filename="file:///home/lexciese/Dev/in-development/altair_ws/install/altair_description/share/altair_description/meshes/la1.stl" scale="1 1 1"/>
      </geometry>
      <material name="Grey">
        <color rgba="0.60 0.60 0.60 1.0"/>
      </material>
    </visual>
    <collision>
      <origin rpy="0 0 0" xyz="0 0 0"/>
      <geometry>
        <mesh filename="file:///home/lexciese/Dev/in-development/altair_ws/install/altair_description/share/altair_description/meshes/la1.stl" scale="1 1 1"/>
      </geometry>
      <material name="Grey">
        <color rgba="0.60 0.60 0.60 1.0"/>
      </material>
    </collision>
    <inertial>
      <origin xyz="0.0 0.00823 -0.00233"/>
      <mass value="0.01176"/>
      <inertia ixx="0.00000165" ixy="0.0" ixz="0.0" iyy="0.00000387" iyz="0.00000031" izz="0.00000397"/>
    </inertial>
  </link>
  <!-- left shoulder roll joint -->
  <joint name="l_sho_roll" type="revolute">
    <parent link="l_sho_pitch_link"/>
    <child link="l_sho_roll_link"/>
    <origin rpy="0 0 0" xyz="0.019 0.0285 -0.010"/>
    <axis xyz="-1 0 0"/>
    <limit effort="1000" lower="-2.827433388230814" upper="2.827433388230814" velocity="100"/>
    <dynamics damping="0.1" friction="0.0"/>
  </joint>
  <!-- left shoulder roll link -->
  <link name="l_sho_roll_link">
    <visual>
      <origin rpy="0 0 0" xyz="0 0 0"/>
      <geometry>
        <mesh filename="file:///home/lexciese/Dev/in-development/altair_ws/install/altair_description/share/altair_description/meshes/la2.stl" scale="1 1 1"/>
      </geometry>
      <material name="Grey">
        <color rgba="0.60 0.60 0.60 1.0"/>
      </material>
    </visual>
    <collision>
      <origin rpy="0 0 0" xyz="0 0 0"/>
      <geometry>
        <mesh filename="file:///home/lexciese/Dev/in-development/altair_ws/install/altair_description/share/altair_description/meshes/la2.stl" scale="1 1 1"/>
      </geometry>
      <material name="Grey">
        <color rgba="0.60 0.60 0.60 1.0"/>
      </material>
    </collision>
    <inertial>
      <origin xyz="-0.01844 0.04514 0.00028"/>
      <mass value="0.17758"/>
      <inertia ixx="0.00022804" ixy="-0.00000001" ixz="0.00000003" iyy="0.00003042" iyz="0.00000059" izz="0.00023474"/>
    </inertial>
  </link>
  <!-- left elbow joint -->
  <joint name="l_el" type="revolute">
    <parent link="l_sho_roll_link"/>
    <child link="l_el_link"/>
    <origin rpy="0 0 0" xyz="0.0 0.0904 -0.0001"/>
    <axis xyz="1 0 0"/>
    <limit effort="1000" lower="-2.827433388230814" upper="2.827433388230814" velocity="100"/>
    <dynamics damping="0.1" friction="0.0"/>
  </joint>
  <!-- left elbow link -->
  <link name="l_el_link">
    <visual>
      <origin rpy="0 0 0" xyz="0 0 0"/>
      <geometry>
        <mesh filename="file:///home/lexciese/Dev/in-development/altair_ws/install/altair_description/share/altair_description/meshes/la3.stl" scale="1 1 1"/>
      </geometry>
      <material name="Grey">
        <color rgba="0.60 0.60 0.60 1.0"/>
      </material>
    </visual>
    <collision>
      <origin rpy="0 0 0" xyz="0 0 0"/>
      <geometry>
        <mesh filename="file:///home/lexciese/Dev/in-development/altair_ws/install/altair_description/share/altair_description/meshes/la3.stl" scale="1 1 1"/>
      </geometry>
      <material name="Grey">
        <color rgba="0.60 0.60 0.60 1.0"/>
      </material>
    </collision>
    <inertial>
      <origin xyz="-0.01900 0.07033 0.00380"/>
      <mass value="0.04127"/>
      <inertia ixx="0.00006196" ixy="0.0" ixz="0.0" iyy="0.00001231" iyz="-0.00000372" izz="0.00006854"/>
    </inertial>
  </link>
  <!-- right shoulder pitch joint -->
  <joint name="r_sho_pitch" type="revolute">
    <parent link="body_link"/>
    <child link="r_sho_pitch_link"/>
    <origin rpy="0 0 0" xyz="-0.001 -0.06 0.111"/>
    <axis xyz="0 -1 0"/>
    <limit effort="1000" lower="-2.827433388230814" upper="2.827433388230814" velocity="100"/>
    <dynamics damping="0.1" friction="0.0"/>
  </joint>
  <!-- right shoulder pitch link -->
  <link name="r_sho_pitch_link">
    <visual>
      <origin rpy="0 0 0" xyz="0 0 0"/>
      <geometry>
        <mesh filename="file:///home/lexciese/Dev/in-development/altair_ws/install/altair_description/share/altair_description/meshes/ra1.stl" scale="1 1 1"/>
      </geometry>
      <material name="Grey">
        <color rgba="0.60 0.60 0.60 1.0"/>
      </material>
    </visual>
    <collision>
      <origin rpy="0 0 0" xyz="0 0 0"/>
      <geometry>
        <mesh filename="file:///home/lexciese/Dev/in-development/altair_ws/install/altair_description/share/altair_description/meshes/ra1.stl" scale="1 1 1"/>
      </geometry>
      <material name="Grey">
        <color rgba="0.60 0.60 0.60 1.0"/>
      </material>
    </collision>
    <inertial>
      <origin xyz="0.0 -0.00823 -0.00233"/>
      <mass value="0.01176"/>
      <inertia ixx="0.00000165" ixy="0.0" ixz="0.0" iyy="0.00000387" iyz="-0.00000031" izz="0.00000397"/>
    </inertial>
  </link>
  <!-- right shoulder roll joint -->
  <joint name="r_sho_roll" type="revolute">
    <parent link="r_sho_pitch_link"/>
    <child link="r_sho_roll_link"/>
    <origin rpy="0 0 0" xyz="0.019 -0.0285 -0.010"/>
    <axis xyz="-1 0 0"/>
    <limit effort="1000" lower="-2.827433388230814" upper="2.827433388230814" velocity="100"/>
    <dynamics damping="0.1" friction="0.0"/>
  </joint>
  <!-- right shoulder roll link -->
  <link name="r_sho_roll_link">
    <visual>
      <origin rpy="0 0 0" xyz="0 0 0"/>
      <geometry>
        <mesh filename="file:///home/lexciese/Dev/in-development/altair_ws/install/altair_description/share/altair_description/meshes/ra2.stl" scale="1 1 1"/>
      </geometry>
      <material name="Grey">
        <color rgba="0.60 0.60 0.60 1.0"/>
      </material>
    </visual>
    <collision>
      <origin rpy="0 0 0" xyz="0 0 0"/>
      <geometry>
        <mesh filename="file:///home/lexciese/Dev/in-development/altair_ws/install/altair_description/share/altair_description/meshes/ra2.stl" scale="1 1 1"/>
      </geometry>
      <material name="Grey">
        <color rgba="0.60 0.60 0.60 1.0"/>
      </material>
    </collision>
    <inertial>
      <origin xyz="-0.01844 -0.04514 0.00028"/>
      <mass value="0.17758"/>
      <inertia ixx="0.00022804" ixy="0.00000001" ixz="0.00000003" iyy="0.00003042" iyz="-0.00000059" izz="0.00023474"/>
    </inertial>
  </link>
  <!-- right elbow joint -->
  <joint name="r_el" type="revolute">
    <parent link="r_sho_roll_link"/>
    <child link="r_el_link"/>
    <origin rpy="0 0 0" xyz="0.0 -0.0904 -0.0001"/>
    <axis xyz="1 0 0"/>
    <limit effort="1000" lower="-2.827433388230814" upper="2.827433388230814" velocity="100"/>
    <dynamics damping="0.1" friction="0.0"/>
  </joint>
  <!-- right elbow link -->
  <link name="r_el_link">
    <visual>
      <origin rpy="0 0 0" xyz="0 0 0"/>
      <geometry>
        <mesh filename="file:///home/lexciese/Dev/in-development/altair_ws/install/altair_description/share/altair_description/meshes/ra3.stl" scale="1 1 1"/>
      </geometry>
      <material name="Grey">
        <color rgba="0.60 0.60 0.60 1.0"/>
      </material>
    </visual>
    <collision>
      <origin rpy="0 0 0" xyz="0 0 0"/>
      <geometry>
        <mesh filename="file:///home/lexciese/Dev/in-development/altair_ws/install/altair_description/share/altair_description/meshes/ra3.stl" scale="1 1 1"/>
      </geometry>
      <material name="Grey">
        <color rgba="0.60 0.60 0.60 1.0"/>
      </material>
    </collision>
    <inertial>
      <origin xyz="-0.01900 -0.07033 0.00380"/>
      <mass value="0.04127"/>
      <inertia ixx="0.00006196" ixy="0.0" ixz="0.0" iyy="0.00001231" iyz="0.00000372" izz="0.00006854"/>
    </inertial>
  </link>
  <!-- head yaw joint -->
  <joint name="head_pan" type="revolute">
    <parent link="body_link"/>
    <child link="head_pan_link"/>
    <origin rpy="0 0 0" xyz="-0.001 0.0 0.1365"/>
    <axis xyz="0 0 1"/>
    <limit effort="1000" lower="-2.827433388230814" upper="2.827433388230814" velocity="100"/>
    <dynamics damping="0.1" friction="0.0"/>
  </joint>
  <!-- head yaw link -->
  <link name="head_pan_link">
    <visual>
      <origin rpy="0 0 0" xyz="0 0 0"/>
      <geometry>
        <mesh filename="file:///home/lexciese/Dev/in-development/altair_ws/install/altair_description/share/altair_description/meshes/h1.stl" scale="1 1 1"/>
      </geometry>
      <material name="Grey">
        <color rgba="0.60 0.60 0.60 1.0"/>
      </material>
    </visual>
    <collision>
      <origin rpy="0 0 0" xyz="0 0 0"/>
      <geometry>
        <mesh filename="file:///home/lexciese/Dev/in-development/altair_ws/install/altair_description/share/altair_description/meshes/h1.stl" scale="1 1 1"/>
      </geometry>
      <material name="Grey">
        <color rgba="0.60 0.60 0.60 1.0"/>
      </material>
    </collision>
    <inertial>
      <origin xyz="0.00233 0.00000 0.00823"/>
      <mass value="0.01176"/>
      <inertia ixx="0.00000397" ixy="0.0" ixz="-0.00000031" iyy="0.00000165" iyz="0.0" izz="0.00000387"/>
    </inertial>
  </link>
  <!-- head pitch joint -->
  <joint name="head_tilt" type="revolute">
    <parent link="head_pan_link"/>
    <child link="head_tilt_link"/>
    <origin rpy="0 0 0" xyz="0.010 0.019 0.0285"/>
    <axis xyz="0 -1 0"/>
    <limit effort="1000" lower="-2.827433388230814" upper="2.827433388230814" velocity="100"/>
    <dynamics damping="0.1" friction="0.0"/>
  </joint>
  <!-- head yaw link -->
  <link name="head_tilt_link">
    <visual>
      <origin rpy="0 0 0" xyz="0 0 0"/>
      <geometry>
        <mesh filename="file:///home/lexciese/Dev/in-development/altair_ws/install/altair_description/share/altair_description/meshes/h2.stl" scale="1 1 1"/>
      </geometry>
      <material name="Grey">
        <color rgba="0.60 0.60 0.60 1.0"/>
      </material>
    </visual>
    <collision>
      <origin rpy="0 0 0" xyz="0 0 0"/>
      <geometry>
        <mesh filename="file:///home/lexciese/Dev/in-development/altair_ws/install/altair_description/share/altair_description/meshes/h2.stl" scale="1 1 1"/>
      </geometry>
      <material name="Grey">
        <color rgba="0.60 0.60 0.60 1.0"/>
      </material>
    </collision>
    <inertial>
      <origin xyz="0.00230 -0.01863 0.02770"/>
      <mass value="0.13631"/>
      <inertia ixx="0.00010612" ixy="0.00000011" ixz="-0.00000910" iyy="0.00008721" iyz="0.00000084" izz="0.00004529"/>
    </inertial>
  </link>
  <!-- camera joint -->
  <joint name="cam" type="fixed">
    <origin rpy="-1.5707963267948966 0 -1.5707963267948966" xyz="0.01425 -0.019 0.04975"/>
    <parent link="head_tilt_link"/>
    <child link="cam_link"/>
  </joint>
  <joint name="cam_gazebo" type="fixed">
    <origin rpy="0 0 0" xyz="0.01425 -0.019 0.04975"/>
    <parent link="head_tilt_link"/>
    <child link="cam_gazebo_link"/>
  </joint>
  <!-- camera link -->
  <link name="cam_link">
    </link>
  <!-- camera link -->
  <link name="cam_gazebo_link">
    </link>
  <ros2_control name="GazeboSimSystem" type="system">
    <hardware>
      <!-- <plugin>mock_components/GenericSystem</plugin> -->
      <plugin>gz_ros2_control/GazeboSimSystem</plugin>
    </hardware>
    <sensor name="imu_sensor">
      <state_interface name="orientation.x"/>
      <state_interface name="orientation.y"/>
      <state_interface name="orientation.z"/>
      <state_interface name="orientation.w"/>
      <state_interface name="angular_velocity.x"/>
      <state_interface name="angular_velocity.y"/>
      <state_interface name="angular_velocity.z"/>
      <state_interface name="linear_acceleration.x"/>
      <state_interface name="linear_acceleration.y"/>
      <state_interface name="linear_acceleration.z"/>
      <param name="frame_id">imu_link</param>
    </sensor>
    <joint name="head_pan">
      <state_interface name="position"/>
      <command_interface name="position">
        <param name="min">-2.8</param>
        <param name="max">2.8</param>
      </command_interface>
    </joint>
    <joint name="head_tilt">
      <state_interface name="position"/>
      <command_interface name="position">
        <param name="min">-2.8</param>
        <param name="max">2.8</param>
      </command_interface>
    </joint>
    <joint name="l_el">
      <state_interface name="position"/>
      <command_interface name="position">
        <param name="min">-2.8</param>
        <param name="max">2.8</param>
      </command_interface>
    </joint>
    <joint name="l_sho_roll">
      <state_interface name="position"/>
      <command_interface name="position">
        <param name="min">-2.8</param>
        <param name="max">2.8</param>
      </command_interface>
    </joint>
    <joint name="l_sho_pitch">
      <state_interface name="position"/>
      <command_interface name="position">
        <param name="min">-2.8</param>
        <param name="max">2.8</param>
      </command_interface>
    </joint>
    <joint name="r_el">
      <state_interface name="position"/>
      <command_interface name="position">
        <param name="min">-2.8</param>
        <param name="max">2.8</param>
      </command_interface>
    </joint>
    <joint name="r_sho_roll">
      <state_interface name="position"/>
      <command_interface name="position">
        <param name="min">-2.8</param>
        <param name="max">2.8</param>
      </command_interface>
    </joint>
    <joint name="r_sho_pitch">
      <state_interface name="position"/>
      <command_interface name="position">
        <param name="min">-2.8</param>
        <param name="max">2.8</param>
      </command_interface>
    </joint>
    <joint name="l_ank_roll">
      <state_interface name="position"/>
      <command_interface name="position">
        <param name="min">-2.8</param>
        <param name="max">2.8</param>
      </command_interface>
    </joint>
    <joint name="l_ank_pitch">
      <state_interface name="position"/>
      <command_interface name="position">
        <param name="min">-2.8</param>
        <param name="max">2.8</param>
      </command_interface>
    </joint>
    <joint name="l_knee">
      <state_interface name="position"/>
      <command_interface name="position">
        <param name="min">-2.8</param>
        <param name="max">2.8</param>
      </command_interface>
    </joint>
    <joint name="l_hip_pitch">
      <state_interface name="position"/>
      <command_interface name="position">
        <param name="min">-2.8</param>
        <param name="max">2.8</param>
      </command_interface>
    </joint>
    <joint name="l_hip_roll">
      <state_interface name="position"/>
      <command_interface name="position">
        <param name="min">-2.8</param>
        <param name="max">2.8</param>
      </command_interface>
    </joint>
    <joint name="l_hip_yaw">
      <state_interface name="position"/>
      <command_interface name="position">
        <param name="min">-2.8</param>
        <param name="max">2.8</param>
      </command_interface>
    </joint>
    <joint name="r_ank_roll">
      <state_interface name="position"/>
      <command_interface name="position">
        <param name="min">-2.8</param>
        <param name="max">2.8</param>
      </command_interface>
    </joint>
    <joint name="r_ank_pitch">
      <state_interface name="position"/>
      <command_interface name="position">
        <param name="min">-2.8</param>
        <param name="max">2.8</param>
      </command_interface>
    </joint>
    <joint name="r_knee">
      <state_interface name="position"/>
      <command_interface name="position">
        <param name="min">-2.8</param>
        <param name="max">2.8</param>
      </command_interface>
    </joint>
    <joint name="r_hip_pitch">
      <state_interface name="position"/>
      <command_interface name="position">
        <param name="min">-2.8</param>
        <param name="max">2.8</param>
      </command_interface>
    </joint>
    <joint name="r_hip_roll">
      <state_interface name="position"/>
      <command_interface name="position">
        <param name="min">-2.8</param>
        <param name="max">2.8</param>
      </command_interface>
    </joint>
    <joint name="r_hip_yaw">
      <state_interface name="position"/>
      <command_interface name="position">
        <param name="min">-2.8</param>
        <param name="max">2.8</param>
      </command_interface>
    </joint>
  </ros2_control>
  <!-- ros_control plugin -->
  <gazebo>
    <plugin filename="gz_ros2_control-system" name="gz_ros2_control::GazeboSimROS2ControlPlugin">
      <parameters>/home/lexciese/Dev/in-development/altair_ws/install/altair_description/share/altair_description/config/alfarobi_config.yaml</parameters>
    </plugin>
  </gazebo>
  <!-- <gazebo reference="cam_gazebo_link">
      <sensor name="camera" type="camera">
        <always_on>true</always_on>
        <visualize>true</visualize>
        <update_rate>30</update_rate>
        <topic>gazebo/camera/image_raw</topic>
        <gz_frame_id>cam_link</gz_frame_id>
        <camera name="__default__">
          <camera_info_topic>gazebo/camera/camera_info</camera_info_topic>
          <horizontal_fov>1.012300</horizontal_fov>
          <image>
            <width>320</width>
            <height>200</height>
          </image>
          <clip>
            <near>0.001000</near>
            <far>100.000000</far>
          </clip>
        </camera>
      </sensor>
    </gazebo> -->
  <!-- imu sensor -->
  <gazebo reference="imu_link">
    <gravity>true</gravity>
    <sensor name="imu_sensor" type="imu">
      <always_on>1</always_on>
      <update_rate>30</update_rate>
      <visualize>true</visualize>
      <topic>gazebo/imu</topic>
      <pose>0 0 0 0 0 0</pose>
    </sensor>
  </gazebo>
</robot>
